<robot name = "robot">
    <link name="Torso">
        <inertial>
            <origin xyz="0 0 1" rpy="0 0 0"/>
            <mass value="1" />
            <inertia ixx="100" ixy="0" ixz="0" iyy="100" iyz="0" izz="100" />
        </inertial>
        <visual>
            <origin xyz="0 0 1" rpy="0 0 0"/>
            <geometry>
                <box size="1.5 0.5 0.2" />
            </geometry>
            <material name="Cyan">
                <color rgba="0 1.0 1.0 1.0"/>
            </material>
        </visual>
        <collision>
            <origin xyz="0 0 1" rpy="0 0 0"/>
            <geometry>
                <box size="1.5 0.5 0.2" />
            </geometry>
        </collision>
    </link>
    <joint name="Torso_BackRightHip" type="revolute">
       <parent link="Torso"/>
       <child  link="BackRightHip"/>
       <origin rpy="0 0 0" xyz="0.675 0.25 1" />
       <axis xyz="1 0 0"/>
       <limit effort="0.0" lower="-0.0" upper="0.0" velocity="0.0"/>
    </joint>
    <joint name="Torso_BackLeftHip" type="revolute">
       <parent link="Torso"/>
       <child  link="BackLeftHip"/>
       <origin rpy="0 0 0" xyz="0.675 -0.25 1" />
       <axis xyz="1 0 0"/>
       <limit effort="0.0" lower="-0.0" upper="0.0" velocity="0.0"/>
    </joint>
    <joint name="Torso_FrontRightHip" type="revolute">
       <parent link="Torso"/>
       <child  link="FrontRightHip"/>
       <origin rpy="0 0 0" xyz="-0.675 0.25 1" />
       <axis xyz="1 0 0"/>
       <limit effort="0.0" lower="-0.0" upper="0.0" velocity="0.0"/>
    </joint>
    <joint name="Torso_FrontLeftHip" type="revolute">
       <parent link="Torso"/>
       <child  link="FrontLeftHip"/>
       <origin rpy="0 0 0" xyz="-0.675 -0.25 1" />
       <axis xyz="1 0 0"/>
       <limit effort="0.0" lower="-0.0" upper="0.0" velocity="0.0"/>
    </joint>
    <link name="BackRightHip">
        <inertial>
            <origin xyz="0 0 0" rpy="0 0 0"/>
            <mass value="1" />
            <inertia ixx="100" ixy="0" ixz="0" iyy="100" iyz="0" izz="100" />
        </inertial>
        <visual>
            <origin xyz="0 0 0" rpy="0 0 0"/>
            <geometry>
                <box size="0.1 0.1 0.1" />
            </geometry>
            <material name="Cyan">
                <color rgba="0 1.0 1.0 1.0"/>
            </material>
        </visual>
        <collision>
            <origin xyz="0 0 0" rpy="0 0 0"/>
            <geometry>
                <box size="0.1 0.1 0.1" />
            </geometry>
        </collision>
    </link>
    <link name="BackLeftHip">
        <inertial>
            <origin xyz="0 0 0" rpy="0 0 0"/>
            <mass value="1" />
            <inertia ixx="100" ixy="0" ixz="0" iyy="100" iyz="0" izz="100" />
        </inertial>
        <visual>
            <origin xyz="0 0 0" rpy="0 0 0"/>
            <geometry>
                <box size="0.15 0 0.15" />
            </geometry>
            <material name="Cyan">
                <color rgba="0 1.0 1.0 1.0"/>
            </material>
        </visual>
        <collision>
            <origin xyz="0 0 0" rpy="0 0 0"/>
            <geometry>
                <box size="0.15 0 0.15" />
            </geometry>
        </collision>
    </link>
    <link name="FrontRightHip">
        <inertial>
            <origin xyz="0 0 0" rpy="0 0 0"/>
            <mass value="1" />
            <inertia ixx="100" ixy="0" ixz="0" iyy="100" iyz="0" izz="100" />
        </inertial>
        <visual>
            <origin xyz="0 0 0" rpy="0 0 0"/>
            <geometry>
                <box size="0.15 0 0.15" />
            </geometry>
            <material name="Cyan">
                <color rgba="0 1.0 1.0 1.0"/>
            </material>
        </visual>
        <collision>
            <origin xyz="0 0 0" rpy="0 0 0"/>
            <geometry>
                <box size="0.15 0 0.15" />
            </geometry>
        </collision>
    </link>
    <link name="FrontLeftHip">
        <inertial>
            <origin xyz="0 0 0" rpy="0 0 0"/>
            <mass value="1" />
            <inertia ixx="100" ixy="0" ixz="0" iyy="100" iyz="0" izz="100" />
        </inertial>
        <visual>
            <origin xyz="0 0 0" rpy="0 0 0"/>
            <geometry>
                <box size="0.15 0 0.15" />
            </geometry>
            <material name="Cyan">
                <color rgba="0 1.0 1.0 1.0"/>
            </material>
        </visual>
        <collision>
            <origin xyz="0 0 0" rpy="0 0 0"/>
            <geometry>
                <box size="0.15 0 0.15" />
            </geometry>
        </collision>
    </link>
    <joint name="BackRightHip_BackRightLeg" type="revolute">
       <parent link="BackRightHip"/>
       <child  link="BackRightLeg"/>
       <origin rpy="0 -0.8726646259971648 0" xyz="0 0 0" />
       <axis xyz="0 1 0"/>
       <limit effort="0.0" lower="-1.5882496193148399" upper="1.5882496193148399" velocity="0.0"/>
    </joint>
    <joint name="BackLeftHip_BackLeftLeg" type="revolute">
       <parent link="BackLeftHip"/>
       <child  link="BackLeftLeg"/>
       <origin rpy="0 -0.8726646259971648 0" xyz="0 0 0" />
       <axis xyz="0 1 0"/>
       <limit effort="0.0" lower="-1.5882496193148399" upper="1.5882496193148399" velocity="0.0"/>
    </joint>
    <joint name="FrontRightHip_FrontRightLeg" type="revolute">
       <parent link="FrontRightHip"/>
       <child  link="FrontRightLeg"/>
       <origin rpy="0 -0.8726646259971648 0" xyz="0 0 0" />
       <axis xyz="0 1 0"/>
       <limit effort="0.0" lower="-1.5882496193148399" upper="1.5882496193148399" velocity="0.0"/>
    </joint>
    <joint name="FrontLeftHip_FrontLeftLeg" type="revolute">
       <parent link="FrontLeftHip"/>
       <child  link="FrontLeftLeg"/>
       <origin rpy="0 -0.8726646259971648 0" xyz="0 0 0" />
       <axis xyz="0 1 0"/>
       <limit effort="0.0" lower="-1.5882496193148399" upper="1.5882496193148399" velocity="0.0"/>
    </joint>
    <link name="BackRightLeg">
        <inertial>
            <origin xyz="0 0.05 -0.3" rpy="0 0 0"/>
            <mass value="1" />
            <inertia ixx="100" ixy="0" ixz="0" iyy="100" iyz="0" izz="100" />
        </inertial>
        <visual>
            <origin xyz="0 0.05 -0.3" rpy="0 0 0"/>
            <geometry>
                <box size="0.15 0.1 0.75" />
            </geometry>
            <material name="Cyan">
                <color rgba="0 1.0 1.0 1.0"/>
            </material>
        </visual>
        <collision>
            <origin xyz="0 0.05 -0.3" rpy="0 0 0"/>
            <geometry>
                <box size="0.15 0.1 0.75" />
            </geometry>
        </collision>
    </link>
    <link name="BackLeftLeg">
        <inertial>
            <origin xyz="0 -0.05 -0.3" rpy="0 0 0"/>
            <mass value="1" />
            <inertia ixx="100" ixy="0" ixz="0" iyy="100" iyz="0" izz="100" />
        </inertial>
        <visual>
            <origin xyz="0 -0.05 -0.3" rpy="0 0 0"/>
            <geometry>
                <box size="0.15 0.1 0.75" />
            </geometry>
            <material name="Cyan">
                <color rgba="0 1.0 1.0 1.0"/>
            </material>
        </visual>
        <collision>
            <origin xyz="0 -0.05 -0.3" rpy="0 0 0"/>
            <geometry>
                <box size="0.15 0.1 0.75" />
            </geometry>
        </collision>
    </link>
    <link name="FrontRightLeg">
        <inertial>
            <origin xyz="0 0.05 -0.3" rpy="0 0 0"/>
            <mass value="1" />
            <inertia ixx="100" ixy="0" ixz="0" iyy="100" iyz="0" izz="100" />
        </inertial>
        <visual>
            <origin xyz="0 0.05 -0.3" rpy="0 0 0"/>
            <geometry>
                <box size="0.15 0.1 0.75" />
            </geometry>
            <material name="Cyan">
                <color rgba="0 1.0 1.0 1.0"/>
            </material>
        </visual>
        <collision>
            <origin xyz="0 0.05 -0.3" rpy="0 0 0"/>
            <geometry>
                <box size="0.15 0.1 0.75" />
            </geometry>
        </collision>
    </link>
    <link name="FrontLeftLeg">
        <inertial>
            <origin xyz="0 -0.05 -0.3" rpy="0 0 0"/>
            <mass value="1" />
            <inertia ixx="100" ixy="0" ixz="0" iyy="100" iyz="0" izz="100" />
        </inertial>
        <visual>
            <origin xyz="0 -0.05 -0.3" rpy="0 0 0"/>
            <geometry>
                <box size="0.15 0.1 0.75" />
            </geometry>
            <material name="Cyan">
                <color rgba="0 1.0 1.0 1.0"/>
            </material>
        </visual>
        <collision>
            <origin xyz="0 -0.05 -0.3" rpy="0 0 0"/>
            <geometry>
                <box size="0.15 0.1 0.75" />
            </geometry>
        </collision>
    </link>
    <joint name="BackRightLeg_LowerBackRightLeg" type="revolute">
       <parent link="BackRightLeg"/>
       <child  link="LowerBackRightLeg"/>
       <origin rpy="-0.0 1.7453292519943295 -0.0" xyz="0 0.05 -0.675" />
       <axis xyz="0 1 0"/>
       <limit effort="0.0" lower="-0.6283185307179586" upper="1.9198621771937625" velocity="0.0"/>
    </joint>
    <joint name="BackLeftLeg_LowerBackLeftLeg" type="revolute">
       <parent link="BackLeftLeg"/>
       <child  link="LowerBackLeftLeg"/>
       <origin rpy="-0.0 1.7453292519943295 -0.0" xyz="0 -0.05 -0.675" />
       <axis xyz="0 1 0"/>
       <limit effort="0.0" lower="-0.6283185307179586" upper="1.9198621771937625" velocity="0.0"/>
    </joint>
    <joint name="FrontRightLeg_LowerFrontRightLeg" type="revolute">
       <parent link="FrontRightLeg"/>
       <child  link="LowerFrontRightLeg"/>
       <origin rpy="-0.0 1.7453292519943295 -0.0" xyz="0 0.05 -0.675" />
       <axis xyz="0 1 0"/>
       <limit effort="0.0" lower="-0.6283185307179586" upper="1.9198621771937625" velocity="0.0"/>
    </joint>
    <joint name="FrontLeftLeg_LowerFrontLeftLeg" type="revolute">
       <parent link="FrontLeftLeg"/>
       <child  link="LowerFrontLeftLeg"/>
       <origin rpy="-0.0 1.7453292519943295 -0.0" xyz="0 -0.05 -0.675" />
       <axis xyz="0 1 0"/>
       <limit effort="0.0" lower="-0.6283185307179586" upper="1.9198621771937625" velocity="0.0"/>
    </joint>
    <link name="LowerBackRightLeg">
        <inertial>
            <origin xyz="0 0 -0.375" rpy="0 0 0"/>
            <mass value="1" />
            <inertia ixx="100" ixy="0" ixz="0" iyy="100" iyz="0" izz="100" />
        </inertial>
        <visual>
            <origin xyz="0 0 -0.375" rpy="0 0 0"/>
            <geometry>
                <box size="0.1 0.1 0.75" />
            </geometry>
            <material name="Cyan">
                <color rgba="0 1.0 1.0 1.0"/>
            </material>
        </visual>
        <collision>
            <origin xyz="0 0 -0.375" rpy="0 0 0"/>
            <geometry>
                <box size="0.1 0.1 0.75" />
            </geometry>
        </collision>
    </link>
    <link name="LowerBackLeftLeg">
        <inertial>
            <origin xyz="0 0 -0.375" rpy="0 0 0"/>
            <mass value="1" />
            <inertia ixx="100" ixy="0" ixz="0" iyy="100" iyz="0" izz="100" />
        </inertial>
        <visual>
            <origin xyz="0 0 -0.375" rpy="0 0 0"/>
            <geometry>
                <box size="0.1 0.1 0.75" />
            </geometry>
            <material name="Cyan">
                <color rgba="0 1.0 1.0 1.0"/>
            </material>
        </visual>
        <collision>
            <origin xyz="0 0 -0.375" rpy="0 0 0"/>
            <geometry>
                <box size="0.1 0.1 0.75" />
            </geometry>
        </collision>
    </link>
    <link name="LowerFrontRightLeg">
        <inertial>
            <origin xyz="0 0 -0.375" rpy="0 0 0"/>
            <mass value="1" />
            <inertia ixx="100" ixy="0" ixz="0" iyy="100" iyz="0" izz="100" />
        </inertial>
        <visual>
            <origin xyz="0 0 -0.375" rpy="0 0 0"/>
            <geometry>
                <box size="0.1 0.1 0.75" />
            </geometry>
            <material name="Cyan">
                <color rgba="0 1.0 1.0 1.0"/>
            </material>
        </visual>
        <collision>
            <origin xyz="0 0 -0.375" rpy="0 0 0"/>
            <geometry>
                <box size="0.1 0.1 0.75" />
            </geometry>
        </collision>
    </link>
    <link name="LowerFrontLeftLeg">
        <inertial>
            <origin xyz="0 0 -0.375" rpy="0 0 0"/>
            <mass value="1" />
            <inertia ixx="100" ixy="0" ixz="0" iyy="100" iyz="0" izz="100" />
        </inertial>
        <visual>
            <origin xyz="0 0 -0.375" rpy="0 0 0"/>
            <geometry>
                <box size="0.1 0.1 0.75" />
            </geometry>
            <material name="Cyan">
                <color rgba="0 1.0 1.0 1.0"/>
            </material>
        </visual>
        <collision>
            <origin xyz="0 0 -0.375" rpy="0 0 0"/>
            <geometry>
                <box size="0.1 0.1 0.75" />
            </geometry>
        </collision>
    </link>
    <joint name="Torso_ArmBase" type="revolute">
       <parent link="Torso"/>
       <child  link="ArmBase"/>
       <origin rpy="0 0 0" xyz="-0.65 0 1.1" />
       <axis xyz="0 0 1"/>
       <limit effort="0.0" lower="-0.17453292519943295" upper="0.17453292519943295" velocity="0.0"/>
    </joint>
    <link name="ArmBase">
        <inertial>
            <origin xyz="0 0 0.05" rpy="0 0 0"/>
            <mass value="1" />
            <inertia ixx="100" ixy="0" ixz="0" iyy="100" iyz="0" izz="100" />
        </inertial>
        <visual>
            <origin xyz="0 0 0.05" rpy="0 0 0"/>
            <geometry>
                <box size="0.2 0.2 0.1" />
            </geometry>
            <material name="Cyan">
                <color rgba="0 1.0 1.0 1.0"/>
            </material>
        </visual>
        <collision>
            <origin xyz="0 0 0.05" rpy="0 0 0"/>
            <geometry>
                <box size="0.2 0.2 0.1" />
            </geometry>
        </collision>
    </link>
    <joint name="ArmBase_Arm1" type="revolute">
       <parent link="ArmBase"/>
       <child  link="Arm1"/>
       <origin rpy="0 1.0471975511965976 0" xyz="0 0 0.1" />
       <axis xyz="0 1 0"/>
       <limit effort="0.0" lower="-1.5707963267948966" upper="0.08726646259971647" velocity="0.0"/>
    </joint>
    <link name="Arm1">
        <inertial>
            <origin xyz="0 0 0.325" rpy="0 0 0"/>
            <mass value="1" />
            <inertia ixx="100" ixy="0" ixz="0" iyy="100" iyz="0" izz="100" />
        </inertial>
        <visual>
            <origin xyz="0 0 0.325" rpy="0 0 0"/>
            <geometry>
                <box size="0.1 0.1 0.65" />
            </geometry>
            <material name="Cyan">
                <color rgba="0 1.0 1.0 1.0"/>
            </material>
        </visual>
        <collision>
            <origin xyz="0 0 0.325" rpy="0 0 0"/>
            <geometry>
                <box size="0.1 0.1 0.65" />
            </geometry>
        </collision>
    </link>
    <joint name="Arm1_Arm2" type="revolute">
       <parent link="Arm1"/>
       <child  link="Arm2"/>
       <origin rpy="-0.0 -2.0943951023931953 -0.0" xyz="0 0 0.65" />
       <axis xyz="0 1 0"/>
       <limit effort="0.0" lower="-0.7853981633974483" upper="0.7853981633974483" velocity="0.0"/>
    </joint>
    <link name="Arm2">
        <inertial>
            <origin xyz="0 0 0.325" rpy="0 0 0"/>
            <mass value="1" />
            <inertia ixx="100" ixy="0" ixz="0" iyy="100" iyz="0" izz="100" />
        </inertial>
        <visual>
            <origin xyz="0 0 0.325" rpy="0 0 0"/>
            <geometry>
                <box size="0.1 0.1 0.65" />
            </geometry>
            <material name="Cyan">
                <color rgba="0 1.0 1.0 1.0"/>
            </material>
        </visual>
        <collision>
            <origin xyz="0 0 0.325" rpy="0 0 0"/>
            <geometry>
                <box size="0.1 0.1 0.65" />
            </geometry>
        </collision>
    </link>
    <joint name="Arm2_Arm3" type="revolute">
       <parent link="Arm2"/>
       <child  link="Arm3"/>
       <origin rpy="0 -0.5 0" xyz="0 0 0.65" />
       <axis xyz="0 1 0"/>
       <limit effort="0.0" lower="-0.7853981633974483" upper="0.7853981633974483" velocity="0.0"/>
    </joint>
    <link name="Arm3">
        <inertial>
            <origin xyz="0 0 0.1" rpy="0 0 0"/>
            <mass value="1" />
            <inertia ixx="100" ixy="0" ixz="0" iyy="100" iyz="0" izz="100" />
        </inertial>
        <visual>
            <origin xyz="0 0 0.1" rpy="0 0 0"/>
            <geometry>
                <box size="0.1 0.1 0.2" />
            </geometry>
            <material name="Cyan">
                <color rgba="0 1.0 1.0 1.0"/>
            </material>
        </visual>
        <collision>
            <origin xyz="0 0 0.1" rpy="0 0 0"/>
            <geometry>
                <box size="0.1 0.1 0.2" />
            </geometry>
        </collision>
    </link>
    <joint name="Arm3_Wrist" type="revolute">
       <parent link="Arm3"/>
       <child  link="Wrist"/>
       <origin rpy="0 0 0.7853981633974483" xyz="0 0 0.2" />
       <axis xyz="0 0 1"/>
       <limit effort="0.0" lower="-3.141592653589793" upper="3.141592653589793" velocity="0.0"/>
    </joint>
    <link name="Wrist">
        <inertial>
            <origin xyz="0 0 0.025" rpy="0 0 0"/>
            <mass value="1" />
            <inertia ixx="100" ixy="0" ixz="0" iyy="100" iyz="0" izz="100" />
        </inertial>
        <visual>
            <origin xyz="0 0 0.025" rpy="0 0 0"/>
            <geometry>
                <box size="0.1 0.1 0.05" />
            </geometry>
            <material name="Cyan">
                <color rgba="0 1.0 1.0 1.0"/>
            </material>
        </visual>
        <collision>
            <origin xyz="0 0 0.025" rpy="0 0 0"/>
            <geometry>
                <box size="0.1 0.1 0.05" />
            </geometry>
        </collision>
    </link>
    <joint name="Wrist_Grabber1" type="revolute">
       <parent link="Wrist"/>
       <child  link="Grabber1"/>
       <origin rpy="0 0 0" xyz="0.05 0 0.05" />
       <axis xyz="0 1 0"/>
       <limit effort="0.0" lower="-1.5707963267948966" upper="1.5707963267948966" velocity="0.0"/>
    </joint>
    <link name="Grabber1">
        <inertial>
            <origin xyz="0.025 0 0.1" rpy="0 0 0"/>
            <mass value="1" />
            <inertia ixx="100" ixy="0" ixz="0" iyy="100" iyz="0" izz="100" />
        </inertial>
        <visual>
            <origin xyz="0.025 0 0.1" rpy="0 0 0"/>
            <geometry>
                <box size="0.05 0.05 0.2" />
            </geometry>
            <material name="Cyan">
                <color rgba="0 1.0 1.0 1.0"/>
            </material>
        </visual>
        <collision>
            <origin xyz="0.025 0 0.1" rpy="0 0 0"/>
            <geometry>
                <box size="0.05 0.05 0.2" />
            </geometry>
        </collision>
    </link>
    <joint name="Wrist_Grabber2" type="revolute">
       <parent link="Wrist"/>
       <child  link="Grabber2"/>
       <origin rpy="0 0 0" xyz="-0.05 0 0.05" />
       <axis xyz="0 1 0"/>
       <limit effort="0.0" lower="-1.5707963267948966" upper="1.5707963267948966" velocity="0.0"/>
    </joint>
    <link name="Grabber2">
        <inertial>
            <origin xyz="-0.025 0 0.1" rpy="0 0 0"/>
            <mass value="1" />
            <inertia ixx="100" ixy="0" ixz="0" iyy="100" iyz="0" izz="100" />
        </inertial>
        <visual>
            <origin xyz="-0.025 0 0.1" rpy="0 0 0"/>
            <geometry>
                <box size="0.05 0.05 0.2" />
            </geometry>
            <material name="Cyan">
                <color rgba="0 1.0 1.0 1.0"/>
            </material>
        </visual>
        <collision>
            <origin xyz="-0.025 0 0.1" rpy="0 0 0"/>
            <geometry>
                <box size="0.05 0.05 0.2" />
            </geometry>
        </collision>
    </link>
</robot>